Workbook
Name AddressOfSite: 'General Information'!$D$450:$D$549
Name AmountOfEmissionsTable: 'Environmental Disclosures'!$D$80:$K$179
Name AmountOfEmissionToAir: 'Environmental Disclosures'!$G$80:$I$179
Name AmountOfEmissionToAir_unit: 'Environmental Disclosures'!$C$78
Name AmountOfEmissionToSoil: 'Environmental Disclosures'!$K$80:$K$179
Name AmountOfEmissionToSoil_unit: 'Environmental Disclosures'!$C$78
Name AmountOfEmissionToWater: 'Environmental Disclosures'!$J$80:$J$179
Name AmountOfEmissionToWater_unit: 'Environmental Disclosures'!$C$78
Name AmountOfWaterWithdrawnAtSitesLocatedInAreasOfHighWaterStress: 'Environmental Disclosures'!$D$304
Name AreaOfSiteInBiodiversitySensitiveArea: 'Environmental Disclosures'!$G$188:$I$287
Name AreaOfSiteInBiodiversitySensitiveArea_unit: 'Environmental Disclosures'!$C$186
Name Assets: 'General Information'!$E$326
Name AverageNumberOfAnnualTrainingHoursPerFemaleEmployee: 'Social Disclosures'!$D$158
Name AverageNumberOfAnnualTrainingHoursPerMaleEmployee: 'Social Disclosures'!$D$157
Name AverageNumberOfAnnualTrainingHoursPerNonReportedGenderEmployee: 'Social Disclosures'!$D$160
Name AverageNumberOfAnnualTrainingHoursPerOtherGenderEmployee: 'Social Disclosures'!$D$159
Name BaselineYearMember: 'Environmental Disclosures'!$G$21
Name BasisForPreparation: 'General Information'!$E$122
Name BasisForReporting: 'General Information'!$E$223
Name BreakdownOfAnnualMassFlowOfRelevantMaterialsUsedByTheUndertakingHypercube: 'Environmental Disclosures'!$C$435:$I$534
Name BreakdownOfEnergyConsumptionAxis: 'Environmental Disclosures'!$C$12:$F$14
Name BreakdownOfEnergyConsumptionTable: 'Environmental Disclosures'!$G$12:$K$14
Name CityOfSite: 'General Information'!$F$450:$F$549
Name CountryOfEmploymentContractAxis: 'Social Disclosures'!$C$29:$D$128
Name CountryOfPrimaryOperationsAndLocationOfSignificantAssets: 'General Information'!$E$331
Name CountryOfSite: 'General Information'!$G$450:$G$549
Name DateOfAdoptionOfTransitionPlanForUndertakingNotHavingAdoptedTransitionPlanYet: 'Environmental Disclosures'!$D$62
Name DescriptionOfActionsTakeToAddressTheConfirmedIncidents: 'Social Disclosures'!$D$192
Name DescriptionOfATargetRelatedToAPolicy: 'General Information'!$E$566
Name DescriptionOfATransitionPlanForClimateChangeMitigationIncludingAnExplanationOfHowItIsContributingToReduceGhgEmissions: 'Environmental Disclosures'!$D$58
Name DescriptionOfClimateRelatedHazardsAndClimateRelatedTransitionEvents: 'Environmental Disclosures'!$E$540
Name DescriptionOfHowCircularEconomyPrinciplesAreApplied: 'Environmental Disclosures'!$D$317
Name DescriptionOfKeyElementsOfStrategyThatRelatesToOrAffectsSustainabilityIssues: 'General Information'!$E$577
Name DescriptionOfLimitsToTheDistributionOfProfitsConnectedToTheMutualisticNatureOrToTheNatureOfTheActivitiesConsistingInServicesOfGeneralEconomicInterestSGEI: 'General Information'!$D$562
Name DescriptionOfMainBusinessRelationships: 'General Information'!$E$573
Name DescriptionOfPracticesPoliciesAndOrFutureInitiatives: 'General Information'!$E$565
Name DescriptionOfSignificantGroupsOfProductsAndOrServicesOffered: 'General Information'!$E$571
Name DescriptionOfSignificantMarketsTheUndertakingOperatesIn: 'General Information'!$E$572
Name DescriptionOfSustainabilityRelatedCertificationsOrLabels: 'General Information'!$E$441
Name DescriptionOfTheEffectiveParticipationOfWorkersUsersOrOtherInterestedPartiesOrCommunitiesInGovernance: 'General Information'!$D$560
Name DisclosureOfAnyOtherEnvironmentalAndOrEntitySpecificEnvironmentalDisclosures: 'Environmental Disclosures'!$C$548
Name DisclosureOfAnyOtherGeneralAndOrEntitySpecificInformation: 'General Information'!$C$581
Name DisclosureOfAnyOtherGovernanceAndOrEntitySpecificGovernanceDisclosures: 'Governance Disclosures'!$C$38
Name DisclosureOfAnyOtherSocialAndOrEntitySpecificSocialDisclosures: 'Social Disclosures'!$C$200
Name DisclosureOfHowItHasAssessedTheExposureAndSensitivityOfItsAssetsActivitiesAndValueChainToTheseHazardsAndTransitionEvents: 'Environmental Disclosures'!$E$541
Name DisclosureOfListOfMainActionsTheEntitySeeksInOrderToAchieveItsTargets: 'Environmental Disclosures'!$C$52
Name DisclosureOfWhetherItHasUndertakenClimateChangeAdaptationActionsForAnyClimateRelatedHazardsAndTransitionEvents: 'Environmental Disclosures'!$E$543
Name EmployeeCountingMethodology: 'General Information'!$E$329
Name EmployeesReceivePayEqualOrAboveMinimumWageDeterminedByNationalLawOrCollectiveAgreement: 'Social Disclosures'!$D$147
Name EmployeeTurnoverRate: 'Social Disclosures'!$D$137
Name EnergyConsumptionFromElectricity_NonRenewableEnergyMember: 'Environmental Disclosures'!$J$12
Name EnergyConsumptionFromElectricity_RenewableEnergyMember: 'Environmental Disclosures'!$G$12
Name EnergyConsumptionFromElectricity_TotalRenewableAndNonRenewableEnergyMember: 'Environmental Disclosures'!$K$12
Name EnergyConsumptionFromFuels_NonRenewableEnergyMember: 'Environmental Disclosures'!$J$14
Name EnergyConsumptionFromFuels_RenewableEnergyMember: 'Environmental Disclosures'!$G$14
Name EnergyConsumptionFromFuels_TotalRenewableAndNonRenewableEnergyMember: 'Environmental Disclosures'!$K$14
Name EnergyConsumptionFromSelfGeneratedElectricity_NonRenewableEnergyMember: 'Environmental Disclosures'!$J$13
Name EnergyConsumptionFromSelfGeneratedElectricity_RenewableEnergyMember: 'Environmental Disclosures'!$G$13
Name EnergyConsumptionFromSelfGeneratedElectricity_TotalRenewableAndNonRenewableEnergyMember: 'Environmental Disclosures'!$K$13
Name enum_B2: 'Enumeration Lists'!$R$2:$R$4

Sheet Introduction
B1: =template_label_version -> Version: | C1: 1.1.1
B2: =template_label_publication_date -> Publication date: | C2: 45988
B3: {=IF(ISERROR(CELL("filename",A1)),"Warning: The Digital Template was developed and tested using Microsoft Excel 365. Functionality may be limited or incorrect when using other spreadsheet applications or older versions of Excel.","")}
B10: =template_label_taxonomy_entry_point -> Taxonomy entry point: | C10: https://xbrl.efrag.org/taxonomy/vsme/2025-07-30/vsme-all.xsd
B11: =template_label_select_template_display_language -> Select Template Display Language: | C11: English - Official [en]
B12: =template_label_title_of_report -> Main title of the report | C12: =template_label_main_title_of_report_text -> Sustainability Report
B13: =template_label_subtitle_of_report -> Subtitle of the report | C13: =template_label_subtitle_of_report_text -> Prepared in accordance with the Voluntary Sustainability Reporting Standard for small and medium-sized undertakings (VSME), released by the European Commission on 30 July 2025.
B14: =template_label_vsme_digital_template -> VSME Digital Template
B15: =template_label_the_purpose_of_this_digital_template_is_to_illustrate_how_vsme_reporting_can_be_implemented_in_a_digital_template -> The purpose of this digital template is to illustrate how VSME reporting can be implemented in a digital template. The template reflects the VSME Recommendation as published by the European Commission on 30 July 2025. The template is accompanied by a digital VSME XBRL taxonomy, which represents the digital data model of the disclosures and is available on EFRAG's website. The VSME requires disclosure of comparative information on metrics (paragraph 12). This template enables reporting for one reporting period only. Therefore, it might be used for reporting in the first year only. It is expected that reporting solutions will enable the roll-forward of reporting periods, which would automatically provide the necessary comparative information. This template can be used for data entry and validation. By using an XBRL Converter on EFRAG's website, it can be saved as an XBRL report, in a free and open data format. Excel-named ranges are used to extract the disclosures. Value cells that are empty and do not have any value (neither text nor a number) will not be considered as reported and will not be included in the XBRL report when using the Excel-to-XBRL converter. A few drop-down selection menus in the VSME have more than 100 entries (e.g. the NACE codes under B1, the list of pollutants under B4, the list of wastes under B7). In order to search in the list, users can simply start typing search keywords in the cell. If a security warning is shown, please "Enable Content" in order to allow automatic calculation of GPS coordinates for the list of sites under B1. No content other than the address entered will be sent to the internet and the contents shared with the provider can be found in the Nominatim Usage Policy (Geocoding Policy) and Privacy Policy. All materials developed by the EFRAG Secretariat are released for free and as open source (MIT license), which will enable any stakeholder to further enhance them and integrate them into commercial solutions. However, respecting the license conditions, the reference to EFRAG must be mentioned by the providers of those commercial solutions. It's possible to consult the MIT License in the specific sheet. If you wish to raise an issue with the VSME Digital Template or the Digital Template to XBRL Converter, please do so by creating an issue in the GitHub project.
B18: =template_label_how_to_use_it -> How to use it:
B19: =template_label_0_provide_information_that_is_mandatory_in_order_to_generate_the_vsme_and_xbrl_report -> 0. Provide information that is mandatory in order to generate the VSME and XBRL Report.
B20: =template_label_1_fill_in_the_disclosures_on_the_four_worksheets -> 1. Fill in the disclosures on the four worksheets (General Information, Environmental Disclosures, Social Disclosures, Governance Disclosures) in the white cells framed by a black border. Do not enter information outside of those cells. Searching in drop-downs can be done by typing into the cell. Hints (input messages) are shown in several cells when selecting them.
B21: =template_label_2_find_more_information_on_the_actual_disclosure_requirements_in_the_vsme_standard -> 2. Find more information on the actual disclosure requirements in the VSME Standard and the related guidance linked to each cell. Additional or entity-specific disclosures can be provided in each text box at the end of each worksheet.
B22: =template_label_3_for_open_tables_like_the_list_of_subsidizers_sites_please_expand_the_groups_by_clicking_the_plus -> 3. For open tables like the List of subsidiaries/sites, please expand the groups by clicking the plus [+] icon on the left side. If more rows are needed, they can be added by inserting them between the first and last row. The row IDs in open tables must remain unique per table.
B23: =template_label_4_validate_the_data_entered_by_checking_the_validation_status -> 4. Validate the data entered by checking the validation status. The report is considered incomplete or erroneous if the validation fails, which might result in an invalid XBRL report.
B24: =template_label_5_convert_this_template_to_an_inline_xbrl_report -> 5. Convert this template to an Inline XBRL report (or XBRL-JSON, XBRL-CSV), using the online converter. Pay attention to the XBRL validation performed by the validator.
B25: =template_label_6_the_undertaking_may_also_upload_the_report_to_public_repositories_or_a_webpage -> 6. The undertaking may also upload the report to public repositories or a webpage.
B27: =template_label_cell_background_color_index -> Cell background color index:
B28: =template_label_general_principles -> General Principles | C28: =template_label_indicates_that_the_disclosure_is_from_the_general_principles_of_the_vsme -> Indicates that the disclosure is from the general principles of the VSME.
B29: =template_label_basic_module -> Basic Module | C29: =template_label_indicates_that_the_disclosure_is_from_the_vsme_basic_module -> Indicates that the disclosure is from the VSME Basic Module.
B30: =template_label_comprehensive_module -> Comprehensive Module | C30: =template_label_indicates_that_the_disclosure_is_from_the_vsme_comprehensive_module -> Indicates that the disclosure is from the VSME Comprehensive Module.
C31: =template_label_indicates_that_the_cell_is_automatically_calculated_and_that_no_data_entry_is_required -> Indicates that the cell is automatically calculated and that no data entry is required.
C32: =template_label_indicates_that_the_datapoint_often_a_condition_will_not_be_included_in_the_vsme_and_digital_xbrl_report -> Indicates that the datapoint (often a condition) will not be included in the VSME and digital XBRL report. These cells are provided to facilitate the completion of the disclosure as they either trigger the applicability of the disclosure or they enable the automatic calculation of the disclosure. If the yellow cells are not being used to calculate a value, the total that is to be reported can be entered manually overwriting by the formula.
C33: =template_label_indicates_that_no_data_entry_is_required_unless_certain_logics_are_selected_in_the_disclosure_itself -> Indicates that no data entry is required unless certain logics are selected in the disclosure itself. When one of these logics is selected, then this cell will turn white.
B34: =template_label_validation_missing_value_error_velue_inconsistency_invalid_url -> Validation MISSING VALUE/ERROR/VALUE INCONSISTENCY/INVALID URL | C34: =template_label_indicates_that_either_data_entry_is_incorrect_in_terms_of_format_or_that_certain_information -> Indicates that either data entry is incorrect in terms of format or that certain information is missing in order to correctly report on the disclosure.
B35: Validation OK | C35: =template_label_indicates_that_data_entry_is_ok_and_the_undertaking_can_proceed_to_the_next_disclosure -> Indicates that data entry is OK and the undertaking can proceed to the next disclosure.
C36: =template_label_no_value_can_be_entered_in_the_cell -> No value can be entered in the cell.
B37: [+] | C37: =template_label_lists_can_be_expanded_using_the_plus_button_on_the_left -> Lists can be expanded using the plus [+] button on the left. If the number of rows is not sufficient, additional rows can be added by right clicking the second row and selecting "Insert row".
B43: =template_label_efrag_is_funded_by_the_european_union_through_the_single_market_programme -> EFRAG is funded by the European Union through the Single Market Programme in which the EEA-EFTA countries (Norway, Iceland and Liechtenstein), as well as Kosovo participate. Any views and opinions expressed are however those of the author(s) only and do not necessarily reflect those of the European Union, the European Commission or of countries that participate in the Single Market Programme. Neither the European Union, the European Commission nor countries participating in the Single market Programme can be held responsible for them. © 2025 EFRAG All rights reserved.
B44: =template_label_reproduction_and_use_rights_are_strictly_limited -> Reproduction and use rights are strictly limited. For further details please contact efragsecretariat@efrag.org

Sheet Table of Contents & Validation
C2: =template_label_overall_validation_status_validation -> Overall Validation Status
B3: =template_label_table_of_contents_validation -> Table of Contents | C3: {=IF(SUMPRODUCT(--((C5:C68<>template_label_ok)*(C5:C68<>"-")*(C5:C68<>""))) > 0, template_label_incomplete, template_label_complete)} -> INCOMPLETE
B4: =template_label_contents_grouping_follows_templates_framework -> Contents grouping follows template's framework | C4: =template_label_specific_content_validation_status_validation -> Specific Content Validation Status
B5: =template_label_general_information_validation -> General Information
B6: =template_label_information_on_the_report_necessary_for_xbrl_validation -> · Information on the report necessary for XBRL | C6: =IF( AND( COUNTIF('General Information'!F3:F12, template_label_missing_value) > 0, COUNTIF('General Information'!F3:F12, template_label_error) = 0 ), template_label_missing_value, IF( AND( COUNTIF('General Information'!F3:F12, template_label_error) > 0, COUNTIF('General Information'!F3:F12, template_label_missing_value) = 0 ), template_label_value_inconsistency, IF( AND( COUNTIF('General Information'!F3:F12, template_label_error) > 0, COUNTIF('General Information'!F3:F12, template_label_missing_value) > 0 ), template_label_error_plus_value_inconsistency, template_label_ok ) ) ) -> MISSING VALUE
B7: =template_label_information_on_previous_reporting_period_validation -> · Information on previous reporting period | C7: =IF(COUNTIF('General Information'!F18:F119, template_label_missing_value) > 0, template_label_missing_value, IF(COUNTIF('General Information'!F18:F119, template_label_invalid_url ) > 0, template_label_invalid_url, IF(COUNTIF('General Information'!F18:F119, template_label_value_inconsistency ) > 0, template_label_value_inconsistency, IF(COUNTIF('General Information'!F18:F119, template_label_ok) > 0, template_label_ok, "-")))) -> -
B8: =template_label_basic_module_validation -> Basic Module
B9: =template_label_general_information_validation -> General Information
B10: =template_label_b1_basis_for_preparation_validation -> · B1 - Basis for Preparation | C10: =IF(COUNTIF(C11:C14,template_label_error_plus_missing_value_plus_value_inconsistency)>0,template_label_error_plus_missing_value_plus_value_inconsistency, IF(COUNTIF(C11:C14,template_label_error_plus_value_inconsistency)>0,template_label_error_plus_value_inconsistency, IF(COUNTIF(C11:C14,template_label_error_plus_missing_value)>0,template_label_error_plus_missing_value, IF(COUNTIF(C11:C14,template_label_error)>0,template_label_error, IF(COUNTIF(C11:C14,template_label_missing_value_plus_value_inconsistency)>0,template_label_missing_value_plus_value_inconsistency, IF(COUNTIF(C11:C14,template_label_value_inconsistency)>0,template_label_value_inconsistency, IF(COUNTIF(C11:C14,template_label_missing_value)>0,template_label_missing_value, IF(COUNTIF(C11:C14,template_label_ok)=ROWS(C11:C14),template_label_ok, IF(COUNTIF(C11:C14,"-")=ROWS(C11:C14),"-", template_label_ok))))))))) -> MISSING VALUE
B11: =template_label_basis_for_preparation_and_other_undertakings_general_information_validation -> Basis for Preparation and other undertaking's general information | C11: =IF( AND( COUNTIF('General Information'!F122:F331, template_label_missing_value) > 0, COUNTIF('General Information'!F122:F331, template_label_value_inconsistency) = 0, COUNTIF('General Information'!F122:F331, template_label_error) = 0 ), template_label_missing_value, IF( AND( COUNTIF('General Information'!F122:F331, template_label_value_inconsistency) > 0, COUNTIF('General Information'!F122:F331, template_label_missing_value) = 0, COUNTIF('General Information'!F122:F331, template_label_error) = 0 ), template_label_value_inconsistency, IF( AND( COUNTIF('General Information'!F122:F331, template_label_value_inconsistency) = 0, COUNTIF('General Information'!F122:F331, template_label_missing_value) = 0, COUNTIF('General Information'!F122:F331, template_label_error) > 0 ), template_label_error, IF( AND( COUNTIF('General Information'!F122:F331, template_label_value_inconsistency) > 0, COUNTIF('General Information'!F122:F331, template_label_missing_value) > 0, COUNTIF('General Information'!F122:F331, template_label_error) = 0 ), template_label_missing_value_plus_value_inconsistency, IF( AND( COUNTIF('General Information'!F122:F331, template_label_value_inconsistency) = 0, COUNTIF('General Information'!F122:F331, template_label_missing_value) > 0, COUNTIF('General Information'!F122:F331, template_label_error) > 0 ), template_label_error_plus_missing_value, IF( AND( COUNTIF('General Information'!F122:F331, template_label_value_inconsistency) > 0, COUNTIF('General Information'!F122:F331, template_label_missing_value) = 0, COUNTIF('General Information'!F122:F331, template_label_error) > 0 ), template_label_error_plus_value_inconsistency, IF( AND( COUNTIF('General Information'!F122:F331, template_label_value_inconsistency) > 0, COUNTIF('General Information'!F122:F331, template_label_missing_value) > 0, COUNTIF('General Information'!F122:F331, template_label_error) > 0 ), template_label_error_plus_missing_value_plus_value_inconsistency, template_label_ok ))))))) -> MISSING VALUE
B12: =template_label_list_of_subsidiaries_validation -> List of subsidiaries | C12: =IF( COUNTIF('General Information'!F336:F435, template_label_missing_value) > 0, template_label_missing_value, IF( COUNTIF('General Information'!F336:F435, template_label_ok) > 0, template_label_ok, "-" ) ) -> -
B13: =template_label_disclosure_of_sustainability_related_certifications_or_labels_validation -> Disclosure of sustainability-related certification(s) or label(s) | C13: =IF( COUNTIF('General Information'!I441, template_label_missing_value) > 0, template_label_missing_value, IF( COUNTIF('General Information'!I441, template_label_ok) > 0, template_label_ok, "-" ) ) -> -
B14: =template_label_list_of_sites_validation -> List of site(s) | C14: =IF( COUNTIF('General Information'!I450:I549, template_label_missing_value) > 0, template_label_missing_value, IF( COUNTIF('General Information'!I450:I549, template_label_ok) > 0, template_label_ok, "-" ) ) -> -
B15: =template_label_b2_practices_policies_and_future_initiatives_for_transitioning_towards_a_more_sustainable_economy_validation -> · B2 - Practices, policies and future initiatives for transitioning towards a more sustainable economy | C15: =IF( COUNTIF(C16:C17, template_label_error_plus_missing_value_plus_value_inconsistency) > 0, template_label_error_plus_missing_value_plus_value_inconsistency, IF( COUNTIF(C16:C17, template_label_error_plus_value_inconsistency) > 0, template_label_error_plus_value_inconsistency, IF( COUNTIF(C16:C17, template_label_error_plus_missing_value) > 0, template_label_error_plus_missing_value, IF( COUNTIF(C16:C17, template_label_error) > 0, template_label_error, IF( COUNTIF(C16:C17, template_label_missing_value_plus_value_inconsistency) > 0, template_label_missing_value_plus_value_inconsistency, IF( COUNTIF(C16:C17, template_label_value_inconsistency) > 0, template_label_value_inconsistency, IF( COUNTIF(C16:C17, template_label_missing_value) > 0, template_label_missing_value, IF( COUNTIF(C16:C17, template_label_ok) = ROWS(C16:C17), template_label_ok, IF( COUNTIF(C16:C17, "-") = ROWS(C16:C17), "-", template_label_ok ) ) ) ) ) ) ) ) ) -> -
B16: =template_label_practices_policies_and_future_initiatives_for_transitioning_towards_a_more_sustainable_economy_validation -> Practices, policies and future initiatives for transitioning towards a more sustainable economy | C16: =IF( COUNTIF('General Information'!P556, template_label_missing_value) > 0, template_label_missing_value, IF( COUNTIF('General Information'!P556, template_label_ok) > 0, template_label_ok, "-" ) ) -> -
B17: =template_label_cooperative_specific_disclosures_validation -> Cooperative specific disclosures | C17: {=IF(OR('General Information'!E560:E562=template_label_ok),template_label_ok,"-")} -> -
B18: =template_label_environmental_disclosures_validation -> Environmental Disclosures
B19: =template_label_b3_energy_and_greenhouse_gas_emissions_validation -> · B3 - Energy and greenhouse gas emissions | C19: =IF(COUNTIF(C20:C23,template_label_error_plus_missing_value_plus_value_inconsistency)>0,template_label_error_plus_missing_value_plus_value_inconsistency, IF(COUNTIF(C20:C23,template_label_error_plus_value_inconsistency)>0,template_label_error_plus_value_inconsistency, IF(COUNTIF(C20:C23,template_label_error_plus_missing_value)>0,template_label_error_plus_missing_value, IF(COUNTIF(C20:C23,template_label_error)>0,template_label_error, IF(COUNTIF(C20:C23,template_label_missing_value_plus_value_inconsistency)>0,template_label_missing_value_plus_value_inconsistency, IF(COUNTIF(C20:C23,template_label_value_inconsistency)>0,template_label_value_inconsistency, IF(COUNTIF(C20:C23,template_label_missing_value)>0,template_label_missing_value, IF(COUNTIF(C20:C23,template_label_ok)=ROWS(C20:C23),template_label_ok, IF(COUNTIF(C20:C23,"-")=ROWS(C20:C23),"-", template_label_ok))))))))) -> -
B20: =template_label_total_energy_consumption_in_mwh_validation -> Total Energy Consumption (in MWh) | C20: =IF(COUNTIF('Environmental Disclosures'!L5,template_label_missing_value)>0,template_label_missing_value, IF(COUNTIF('Environmental Disclosures'!L5,template_label_ok)>0,template_label_ok,"-")) -> -
B21: =template_label_breakdown_of_energy_consumption_in_mwh_validation -> Breakdown of energy consumption (in MWh) | C21: =IF( AND( COUNTIF('Environmental Disclosures'!L12:L14,template_label_missing_value)>0, COUNTIF('Environmental Disclosures'!L12:L14,template_label_value_inconsistency)=0 ), template_label_missing_value, IF( AND( COUNTIF('Environmental Disclosures'!L12:L14,template_label_value_inconsistency)>0, COUNTIF('Environmental Disclosures'!L12:L14,template_label_missing_value)=0 ), template_label_value_inconsistency, IF( AND( COUNTIF('Environmental Disclosures'!L12:L14,template_label_value_inconsistency)>0, COUNTIF('Environmental Disclosures'!L12:L14,template_label_missing_value)>0 ), template_label_error_plus_value_inconsistency, IF( COUNTA('Environmental Disclosures'!L12:L14,"-"), "-", template_label_ok ) ) )) -> -
B22: =template_label_estimated_greenhouse_gas_emissions_considering_the_ghg_protocol_version_2004_in_tco2e_validation -> Estimated Greenhouse Gas Emissions considering the GHG Protocol Version 2004 (in tCO2e) | C22: =IF(COUNTIF('Environmental Disclosures'!L21:L44,template_label_missing_value)>0,template_label_missing_value, IF(COUNTIF('Environmental Disclosures'!L21:L44,template_label_ok)>0,template_label_ok,"-")) -> -
B23: =template_label_greenhouse_gas_emission_intensity_per_turnover_validation -> Greenhouse gas emission intensity per turnover | C23: =IF(C22=template_label_ok,template_label_ok,"-") -> -
B24: =template_label_b4_pollution_of_air_water_and_soil_validation -> · B4 - Pollution of air, water and soil | C24: =IF(COUNTIF('Environmental Disclosures'!L75:L179,template_label_invalid_url)>0, template_label_invalid_url, IF(AND(COUNTIF('Environmental Disclosures'!L75:L179,template_label_missing_value)>0, COUNTIF('Environmental Disclosures'!L75:L179,template_label_value_inconsistency)>0), template_label_missing_value_plus_value_inconsistency, IF(COUNTIF('Environmental Disclosures'!L75:L179,template_label_missing_value)>0, template_label_missing_value, IF(COUNTIF('Environmental Disclosures'!L75:L179,template_label_value_inconsistency)>0, template_label_value_inconsistency, IF(COUNTIF('Environmental Disclosures'!L75:L179,template_label_ok)>0, template_label_ok, "-"))))) -> -
B25: =template_label_b5_biodiversity_validation -> · B5 - Biodiversity | C25: =IF(COUNTIF(C26:C27,template_label_error_plus_missing_value_plus_value_inconsistency)>0,template_label_error_plus_missing_value_plus_value_inconsistency, IF(COUNTIF(C26:C27,template_label_error_plus_value_inconsistency)>0,template_label_error_plus_value_inconsistency, IF(COUNTIF(C26:C27,template_label_error_plus_missing_value)>0,template_label_error_plus_missing_value, IF(COUNTIF(C26:C27,template_label_error)>0,template_label_error, IF(COUNTIF(C26:C27,template_label_missing_value_plus_value_inconsistency)>0,template_label_missing_value_plus_value_inconsistency, IF(COUNTIF(C26:C27,template_label_value_inconsistency)>0,template_label_value_inconsistency, IF(COUNTIF(C26:C27,template_label_missing_value)>0,template_label_missing_value, IF(COUNTIF(C26:C27,template_label_ok)=ROWS(C26:C27),template_label_ok, IF(COUNTIF(C26:C27,"-")=ROWS(C26:C27),"-", template_label_ok))))))))) -> -
B26: =template_label_sites_in_biodiversity_sensitive_areas_validation -> Sites in biodiversity sensitive areas | C26: =IF(AND( COUNTIF('Environmental Disclosures'!D188:D287,template_label_ok) + COUNTIF('Environmental Disclosures'!L186:L287,template_label_ok) > 0, COUNTIF('Environmental Disclosures'!D188:D287,template_label_missing_value) + COUNTIF('Environmental Disclosures'!L186:L287,template_label_missing_value) = 0, COUNTIF('Environmental Disclosures'!D188:D287,template_label_value_inconsistency) + COUNTIF('Environmental Disclosures'!L186:L287,template_label_value_inconsistency) = 0), template_label_ok, IF(AND( COUNTIF('Environmental Disclosures'!D188:D287,template_label_missing_value) + COUNTIF('Environmental Disclosures'!L186:L287,template_label_missing_value) > 0, COUNTIF('Environmental Disclosures'!D188:D287,template_label_value_inconsistency) + COUNTIF('Environmental Disclosures'!L186:L287,template_label_value_inconsistency) = 0), template_label_missing_value, IF(AND( COUNTIF('Environmental Disclosures'!D188:D287,template_label_value_inconsistency) + COUNTIF('Environmental Disclosures'!L186:L287,template_label_value_inconsistency) > 0, COUNTIF('Environmental Disclosures'!D188:D287,template_label_missing_value) + COUNTIF('Environmental Disclosures'!L186:L287,template_label_missing_value) = 0), template_label_value_inconsistency, IF(AND( COUNTIF('Environmental Disclosures'!D188:D287,template_label_value_inconsistency) + COUNTIF('Environmental Disclosures'!L186:L287,template_label_value_inconsistency) > 0, COUNTIF('Environmental Disclosures'!D188:D287,template_label_missing_value) + COUNTIF('Environmental Disclosures'!L186:L287,template_label_missing_value) > 0), template_label_missing_value_plus_value_inconsistency, "-" ) ) ) ) -> -
B27: =template_label_biodiversity_land_use_validation -> Biodiversity - Land-use | C27: =IF( AND( COUNTIF('Environmental Disclosures'!G293:G298,template_label_missing_value)>0, COUNTIF('Environmental Disclosures'!G293:G298,template_label_value_inconsistency)=0, COUNTIF('Environmental Disclosures'!G293:G298,template_label_ok)>=0 ), template_label_missing_value, IF( AND( COUNTIF('Environmental Disclosures'!G293:G298,template_label_value_inconsistency)>0, COUNTIF('Environmental Disclosures'!G293:G298,template_label_missing_value)=0, COUNTIF('Environmental Disclosures'!G293:G298,template_label_ok)>=0 ), template_label_value_inconsistency, IF( AND( COUNTIF('Environmental Disclosures'!G293:G298,template_label_value_inconsistency)>0, COUNTIF('Environmental Disclosures'!G293:G298,template_label_missing_value)>0, COUNTIF('Environmental Disclosures'!G293:G298,template_label_ok)>=0 ), template_label_missing_value_plus_value_inconsistency, IF( AND( COUNTIF('Environmental Disclosures'!G293:G298,template_label_value_inconsistency)=0, COUNTIF('Environmental Disclosures'!G293:G298,template_label_missing_value)=0, COUNTIF('Environmental Disclosures'!G293:G298,template_label_ok)>0 ), template_label_ok, "-" ) ) )) -> -
B28: =template_label_b6_water_validation -> · B6 - Water | C28: =IF(COUNTIF(C29:C30,template_label_error_plus_missing_value_plus_value_inconsistency)>0,template_label_error_plus_missing_value_plus_value_inconsistency, IF(COUNTIF(C29:C30,template_label_error_plus_value_inconsistency)>0,template_label_error_plus_value_inconsistency, IF(COUNTIF(C29:C30,template_label_error_plus_missing_value)>0,template_label_error_plus_missing_value, IF(COUNTIF(C29:C30,template_label_error)>0,template_label_error, IF(COUNTIF(C29:C30,template_label_missing_value_plus_value_inconsistency)>0,template_label_missing_value_plus_value_inconsistency, IF(COUNTIF(C29:C30,template_label_value_inconsistency)>0,template_label_value_inconsistency, IF(COUNTIF(C29:C30,template_label_missing_value)>0,template_label_missing_value, IF(COUNTIF(C29:C30,template_label_ok)=ROWS(C29:C30),template_label_ok, IF(COUNTIF(C29:C30,"-")=ROWS(C29:C30),"-", template_label_ok))))))))) -> -
B29: =template_label_water_withdrawal_validation -> Water Withdrawal | C29: =IF(COUNTIF('Environmental Disclosures'!E303:F304, template_label_missing_value) > 0, template_label_missing_value, IF(COUNTIF('Environmental Disclosures'!E303:F304, template_label_ok) > 0, template_label_ok, "-")) -> -
B30: =template_label_water_consumption_validation -> Water Consumption | C30: =IF(COUNTIF('Environmental Disclosures'!E310:F310, template_label_missing_value) > 0, template_label_missing_value, IF(COUNTIF('Environmental Disclosures'!E310:F310, template_label_ok) > 0, template_label_ok, "-")) -> -
B31: =template_label_b7_resource_use_circular_economy_and_waste_management_validation -> · B7 - Resource use, circular economy and waste management | C31: =IF(COUNTIF(C32:C34, template_label_error_plus_missing_value_plus_value_inconsistency) > 0, template_label_error_plus_missing_value_plus_value_inconsistency, IF(COUNTIF(C32:C34, template_label_error_plus_value_inconsistency) > 0, template_label_error_plus_value_inconsistency, IF(COUNTIF(C32:C34, template_label_error_plus_missing_value) > 0, template_label_error_plus_missing_value, IF(COUNTIF(C32:C34, template_label_error) > 0, template_label_error, IF(COUNTIF(C32:C34, template_label_missing_value_plus_value_inconsistency) > 0, template_label_missing_value_plus_value_inconsistency, IF(COUNTIF(C32:C34, template_label_value_inconsistency) > 0, template_label_value_inconsistency, IF(COUNTIF(C32:C34, template_label_missing_value) > 0, template_label_missing_value, IF(COUNTIF(C32:C34, template_label_ok) = ROWS(C32:C34), template_label_ok, IF(COUNTIF(C32:C34, "-") = ROWS(C32:C34), "-", template_label_ok))))))))) -> -
B32: =template_label_description_of_circular_economy_principles_validation -> Description of circular economy principles | C32: =IF( AND( COUNTIF('Environmental Disclosures'!H316:I317, template_label_missing_value) > 0, COUNTIF('Environmental Disclosures'!H316:I317, template_label_value_inconsistency) = 0, COUNTIF('Environmental Disclosures'!H316:I317, template_label_ok) >= 0 ), template_label_missing_value, IF( AND( COUNTIF('Environmental Disclosures'!H316:I317, template_label_value_inconsistency) > 0, COUNTIF('Environmental Disclosures'!H316:I317, template_label_missing_value) = 0, COUNTIF('Environmental Disclosures'!H316:I317, template_label_ok) >= 0 ), template_label_value_inconsistency, IF( AND( COUNTIF('Environmental Disclosures'!H316:I317, template_label_value_inconsistency) > 0, COUNTIF('Environmental Disclosures'!H316:I317, template_label_missing_value) > 0, COUNTIF('Environmental Disclosures'!H316:I317, template_label_ok) >= 0 ), template_label_missing_value_plus_value_inconsistency, IF( AND( COUNTIF('Environmental Disclosures'!H316:I317, template_label_value_inconsistency) = 0, COUNTIF('Environmental Disclosures'!H316:I317, template_label_missing_value) = 0, COUNTIF('Environmental Disclosures'!H316:I317, template_label_ok) > 0 ), template_label_ok, "-" ) ) )) -> -
B33: =template_label_waste_generated_validation -> Waste generated | C33: =IF( AND( COUNTIF('Environmental Disclosures'!M323:M423, template_label_error) > 0, COUNTIF('Environmental Disclosures'!M323:M423, template_label_missing_value) > 0, COUNTIF('Environmental Disclosures'!M323:M423, template_label_value_inconsistency) > 0 ), template_label_error_plus_missing_value_plus_value_inconsistency, IF( AND( COUNTIF('Environmental Disclosures'!M323:M423, template_label_error) > 0, COUNTIF('Environmental Disclosures'!M323:M423, template_label_value_inconsistency) > 0, COUNTIF('Environmental Disclosures'!M323:M423, template_label_missing_value) = 0 ), template_label_error_plus_value_inconsistency, IF( AND( COUNTIF('Environmental Disclosures'!M323:M423, template_label_error) > 0, COUNTIF('Environmental Disclosures'!M323:M423, template_label_missing_value) > 0, COUNTIF('Environmental Disclosures'!M323:M423, template_label_value_inconsistency) = 0 ), template_label_error_plus_missing_value, IF( AND( COUNTIF('Environmental Disclosures'!M323:M423, template_label_missing_value) > 0, COUNTIF('Environmental Disclosures'!M323:M423, template_label_value_inconsistency) > 0, COUNTIF('Environmental Disclosures'!M323:M423, template_label_error) = 0 ), template_label_missing_value_plus_value_inconsistency, IF( AND( COUNTIF('Environmental Disclosures'!M323:M423, template_label_error) > 0, COUNTIF('Environmental Disclosures'!M323:M423, template_label_missing_value) = 0, COUNTIF('Environmental Disclosures'!M323:M423, template_label_value_inconsistency) = 0 ), template_label_error, IF( AND( COUNTIF('Environmental Disclosures'!M323:M423, template_label_missing_value) > 0, COUNTIF('Environmental Disclosures'!M323:M423, template_label_error) = 0, COUNTIF('Environmental Disclosures'!M323:M423, template_label_value_inconsistency) = 0 ), template_label_missing_value, IF( AND( COUNTIF('Environmental Disclosures'!M323:M423, template_label_value_inconsistency) > 0, COUNTIF('Environmental Disclosures'!M323:M423, template_label_error) = 0, COUNTIF('Environmental Disclosures'!M323:M423, template_label_missing_value) = 0 ), template_label_value_inconsistency, IF( AND( COUNTIF('Environmental Disclosures'!M323:M423, template_label_error) = 0, COUNTIF('Environmental Disclosures'!M323:M423, template_label_missing_value) = 0, COUNTIF('Environmental Disclosures'!M323:M423, template_label_value_inconsistency) = 0, COUNTIF('Environmental Disclosures'!M323:M423, template_label_ok) > 0 ), template_label_ok, "-" )))))))) -> -
B34: =template_label_annual_mass_flow_of_relevant_materials_used_validation -> Annual mass-flow of relevant materials used | C34: =IF(COUNTIF('Environmental Disclosures'!K435:K534, template_label_missing_value) > 0, template_label_missing_value, IF(COUNTIF('Environmental Disclosures'!K435:K534, template_label_ok) > 0, template_label_ok, "-")) -> -
B35: =template_label_social_disclosures_validation -> Social Disclosures
B36: =template_label_b8_workforce_general_characteristics_validation -> · B8 - Workforce - General characteristics | C36: =IF(COUNTIF(C37:C40, template_label_error_plus_missing_value_plus_value_inconsistency) > 0, template_label_error_plus_missing_value_plus_value_inconsistency, IF(COUNTIF(C37:C40, template_label_error_plus_value_inconsistency) > 0, template_label_error_plus_value_inconsistency, IF(COUNTIF(C37:C40, template_label_error_plus_missing_value) > 0, template_label_error_plus_missing_value, IF(COUNTIF(C37:C40, template_label_error) > 0, template_label_error, IF(COUNTIF(C37:C40, template_label_missing_value_plus_value_inconsistency) > 0, template_label_missing_value_plus_value_inconsistency, IF(COUNTIF(C37:C40, template_label_value_inconsistency) > 0, template_label_value_inconsistency, IF(COUNTIF(C37:C40, template_label_missing_value) > 0, template_label_missing_value, IF(COUNTIF(C37:C40, template_label_ok) = ROWS(C37:C40), template_label_ok, IF(COUNTIF(C37:C40, "-") = ROWS(C37:C40), "-", template_label_ok))))))))) -> -
B37: =template_label_type_of_contract_validation -> Type of contract | C37: =IF(COUNTIF('Social Disclosures'!H10, template_label_missing_value) > 0, template_label_missing_value, IF(COUNTIF('Social Disclosures'!H10, template_label_ok) > 0, template_label_ok, "-")) -> -
B38: =template_label_gender_validation -> Gender | C38: =IF(COUNTIF('Social Disclosures'!H18:H21, template_label_missing_value) > 0, template_label_missing_value, IF(COUNTIF('Social Disclosures'!H18:H21, template_label_ok) > 0, template_label_ok, "-")) -> -
B39: =template_label_country_of_employment_validation -> Country of employment | C39: =IF(COUNTIF('Social Disclosures'!I29:I128, template_label_missing_value) > 0, template_label_missing_value, IF(COUNTIF('Social Disclosures'!I29:I128, template_label_ok) > 0, template_label_ok, "-")) -> -
B40: =template_label_turnover_rate_validation -> Turnover rate | C40: =IF(COUNTIF('Social Disclosures'!I134:I136, template_label_missing_value) > 0, template_label_missing_value, IF(COUNTIF('Social Disclosures'!I134:I136, template_label_ok) > 0, template_label_ok, "-")) -> -
B41: =template_label_b9_workforce_health_and_safety_validation -> · B9 - Workforce – Health and safety | C41: =IF(COUNTIF('Social Disclosures'!I140:I144, template_label_missing_value) > 0, template_label_missing_value, IF(COUNTIF('Social Disclosures'!I140:I144, template_label_ok) > 0, template_label_ok, "-")) -> -
...

Sheet General Information
A1: =template_label_paragraph_reference -> Paragraph Reference | B1: =template_label_paragraph_guidance_reference -> Paragraph Guidance Reference
C2: =template_label_information_on_the_report_necessary_for_xbrl & " " & template_label_always_to_be_reported -> Information on the report necessary for XBRL [Always to be reported]
C3: =template_label_name_of_the_reporting_entity -> Name of the reporting entity | F3: =IF(D3 = "", template_label_missing_value, template_label_ok) -> MISSING VALUE
C4: =template_label_identifier_of_the_reporting_entity -> Identifier of the reporting entity (select and specify on the right) | F4: =IF(OR(D4 = "", E4 = ""), template_label_missing_value, template_label_ok) -> MISSING VALUE | G4: =template_label_identifier_warning -> ℹ️ The entity identifier is a unique ID, that will enable identifying the company that has reported the information. The VSME Standard does not require any specific identifier. An entity identifier is required for the digital reporting.
C5: =template_label_currency_of_the_monetary_values_in_the_report -> Currency of the monetary values in the report | F5: =IF(D5 = "", template_label_missing_value, template_label_ok) -> MISSING VALUE
C6: =template_label_starting_year -> Starting year | F6: =IF(OR(D6 = "", D7 = "", D8 = ""), template_label_missing_value, IF(OR( AND(D7 = 2, D8 > 29), AND(D7 = 2, D8 = 29, NOT(AND(MOD(D6, 4) = 0, OR(MOD(D6, 100) <> 0, MOD(D6, 400) = 0)))), AND(OR(D7 = 4, D7 = 6, D7 = 9, D7 = 11), D8 = 31) ), template_label_error, IF(F10 = template_label_value_inconsistency, template_label_value_inconsistency, template_label_ok) ) ) -> MISSING VALUE | G6: =template_label_date_warning -> ℹ️ If VALUE INCONSISTENCY message appears on the right, please ensure that the reporting period end date is greater than the reporting period start date.
C7: =template_label_starting_month -> Starting month
C8: =template_label_starting_day -> Starting day
C9: =template_label_reporting_period_start_date -> Reporting period start date (yyyy-mm-dd) | D9: =IF(OR(ISBLANK(D6), ISBLANK(D7), ISBLANK(D8)), "-", D6 & "-" & TEXT(D7, "00") & "-" & TEXT(D8, "00")) -> -
C10: =template_label_ending_year -> Ending year | F10: =IF(OR(D10 = "", D11 = "", D12 = ""), template_label_missing_value, IF(OR( AND(D11 = 2, D12 > 29), AND(D11 = 2, D12 = 29, NOT(AND(MOD(D10, 4) = 0, OR(MOD(D10, 100) <> 0, MOD(D10, 400) = 0)))), AND(OR(D11 = 4, D11 = 6, D11 = 9, D11 = 11), D12 = 31) ), template_label_error, IF(D10 < D6, template_label_value_inconsistency, IF(D10 > D6, template_label_ok, IF(AND(D10 = D6, MATCH(D11, {1;2;3;4;5;6;7;8;9;10;11;12}, 0) < MATCH(D7, {1;2;3;4;5;6;7;8;9;10;11;12}, 0)), template_label_value_inconsistency, IF(AND(D10 = D6, MATCH(D11, {1;2;3;4;5;6;7;8;9;10;11;12}, 0) > MATCH(D7, {1;2;3;4;5;6;7;8;9;10;11;12}, 0)), template_label_ok, IF(AND(D10 = D6, MATCH(D11, {1;2;3;4;5;6;7;8;9;10;11;12}, 0) = MATCH(D7, {1;2;3;4;5;6;7;8;9;10;11;12}, 0), D12 < D8), template_label_value_inconsistency, template_label_ok ))))))) -> MISSING VALUE | G10: =template_label_date_warning -> ℹ️ If VALUE INCONSISTENCY message appears on the right, please ensure that the reporting period end date is greater than the reporting period start date.
C11: =template_label_ending_month -> Ending month
C12: Ending day
C13: =template_label_reporting_period_end_date -> Reporting period end date (yyyy-mm-dd) | D13: =IF(OR(ISBLANK(D10), ISBLANK(D11), ISBLANK(D12)), "-", D10 & "-" & TEXT(D11, "00") & "-" & TEXT(D12, "00")) -> -
C16: =template_label_information_on_previous_reporting_period -> Information on previous reporting period
C17: 16
C18: =template_label_disclosures_from_the_previous_reporting_period_that_remain_unchanged -> This report contains disclosures from the previous reporting period that remain unchanged | E18: FALSE | F18: =IF(E18 = FALSE, "", template_label_ok)
C19: =template_label_disclosures_for_which_no_changes_are_reported_compared_to_the_previous_period_reporting -> List of disclosures for which no changes are reported compared to the previous period reporting | F19: =IF(AND(E18 = FALSE, E19 = ""), "", IF(AND(E18 = FALSE, E19 <> ""), "", IF(AND(E18 = TRUE, E19 = ""), template_label_missing_value, IF(AND(E18 = TRUE, E19 <> "", COUNTIF(E19:E118, E19) = COUNTA(E19:E118), COUNTA(E19:E118) > 1), template_label_value_inconsistency, template_label_ok)))) | G19: =template_label_additional_rows_warning -> ℹ️ Lists can be expanded using the little [+] button on the left. If the number of rows is not sufficient, those can be added by right clicking the second row and selecting "Insert row".
F20: =IF($E$18 = FALSE, "", IF(E20 = "", "", IF(COUNTIF($E$19:$E$118, E20) > 1, template_label_value_inconsistency, template_label_ok)))
F21: =IF($E$18 = FALSE, "", IF(E21 = "", "", IF(COUNTIF($E$19:$E$118, E21) > 1, template_label_value_inconsistency, template_label_ok)))
F22: =IF($E$18 = FALSE, "", IF(E22 = "", "", IF(COUNTIF($E$19:$E$118, E22) > 1, template_label_value_inconsistency, template_label_ok)))
F23: =IF($E$18 = FALSE, "", IF(E23 = "", "", IF(COUNTIF($E$19:$E$118, E23) > 1, template_label_value_inconsistency, template_label_ok)))
F24: =IF($E$18 = FALSE, "", IF(E24 = "", "", IF(COUNTIF($E$19:$E$118, E24) > 1, template_label_value_inconsistency, template_label_ok)))
F25: =IF($E$18 = FALSE, "", IF(E25 = "", "", IF(COUNTIF($E$19:$E$118, E25) > 1, template_label_value_inconsistency, template_label_ok)))
F26: =IF($E$18 = FALSE, "", IF(E26 = "", "", IF(COUNTIF($E$19:$E$118, E26) > 1, template_label_value_inconsistency, template_label_ok)))
F27: =IF($E$18 = FALSE, "", IF(E27 = "", "", IF(COUNTIF($E$19:$E$118, E27) > 1, template_label_value_inconsistency, template_label_ok)))
C119: =template_label_link_to_previous_report_containing_disclosures_that_remain_unchanged -> Link to previous report containing disclosures that remain unchanged | F119: =IF(AND(E18 = FALSE, E119 = ""), "", IF(AND(E18 = TRUE, E119 = ""), template_label_missing_value, IF(AND(E18 = FALSE, E119 <> ""), "", IF(AND(E18 = TRUE, E119 <> "", OR(LEFT(E119, 7) = "http://", LEFT(E119, 8) = "https://", LEFT(E119, 4) = "www.")), template_label_ok, IF(E18 = TRUE, template_label_invalid_url, template_label_missing_value)))))
C121: =template_label_b1_basis_for_preparation_and_other_undertakings_general_information & " " & template_label_from & " " & template_starting_date_display & " " & template_label_to & " " & template_ending_date_display & " " & template_label_always_to_be_reported -> B1 - Basis for Preparation and other undertaking's general information from - to - [Always to be reported]
A122: 24(a) | B122: N/A | C122: =template_label_basis_for_preparation -> Basis for preparation (Basic Module Only or Basic & Comprehensive Module) | F122: =IF(E122 = "", template_label_missing_value, template_label_ok) -> MISSING VALUE
A123: 24(b) | B123: N/A | C123: =template_label_list_of_omitted_disclosures_deemed_to_be_classified_or_sensitive_information -> List of omitted disclosures deemed to be classified or sensitive information | F123: =IF(E122 = "", "", IF(AND(OR(E122 = "Option A (Basic Module only)", E122 = "Option B (Basic Module and Comprehensive Module)"), E123 = ""), template_label_missing_value, IF(COUNTIF(E123:E223, E123) > 1, template_label_value_inconsistency, template_label_ok)))
F124: =IF(AND($E$123 = "None", E124 <> ""), template_label_value_inconsistency, IF(E124 = "", "", IF(COUNTIF($E$123:$E$222, E124) > 1, template_label_value_inconsistency, template_label_ok)))
F125: =IF(AND($E$123 = "None", E125 <> ""), template_label_value_inconsistency, IF(E125 = "", "", IF(COUNTIF($E$123:$E$222, E125) > 1, template_label_value_inconsistency, template_label_ok)))
F126: =IF(AND($E$123 = "None", E126 <> ""), template_label_value_inconsistency, IF(E126 = "", "", IF(COUNTIF($E$123:$E$222, E126) > 1, template_label_value_inconsistency, template_label_ok)))
F127: =IF(AND($E$123 = "None", E127 <> ""), template_label_value_inconsistency, IF(E127 = "", "", IF(COUNTIF($E$123:$E$222, E127) > 1, template_label_value_inconsistency, template_label_ok)))
F128: =IF(AND($E$123 = "None", E128 <> ""), template_label_value_inconsistency, IF(E128 = "", "", IF(COUNTIF($E$123:$E$222, E128) > 1, template_label_value_inconsistency, template_label_ok)))
F129: =IF(AND($E$123 = "None", E129 <> ""), template_label_value_inconsistency, IF(E129 = "", "", IF(COUNTIF($E$123:$E$222, E129) > 1, template_label_value_inconsistency, template_label_ok)))
F130: =IF(AND($E$123 = "None", E130 <> ""), template_label_value_inconsistency, IF(E130 = "", "", IF(COUNTIF($E$123:$E$222, E130) > 1, template_label_value_inconsistency, template_label_ok)))
F131: =IF(AND($E$123 = "None", E131 <> ""), template_label_value_inconsistency, IF(E131 = "", "", IF(COUNTIF($E$123:$E$222, E131) > 1, template_label_value_inconsistency, template_label_ok)))
F132: =IF(AND($E$123 = "None", E132 <> ""), template_label_value_inconsistency, IF(E132 = "", "", IF(COUNTIF($E$123:$E$222, E132) > 1, template_label_value_inconsistency, template_label_ok)))
F133: =IF(AND($E$123 = "None", E133 <> ""), template_label_value_inconsistency, IF(E133 = "", "", IF(COUNTIF($E$123:$E$222, E133) > 1, template_label_value_inconsistency, template_label_ok)))
F134: =IF(AND($E$123 = "None", E134 <> ""), template_label_value_inconsistency, IF(E134 = "", "", IF(COUNTIF($E$123:$E$222, E134) > 1, template_label_value_inconsistency, template_label_ok)))
...

Sheet Environmental Disclosures
A1: =template_label_paragraph_reference -> Paragraph Reference | B1: =template_label_paragraph_guidance_reference -> Paragraph Guidance Reference
C2: =template_label_b3_total_energy_consumption&" "&template_label_from&" "&template_starting_date_display&" "&template_label_to&" "&template_ending_date_display&" "&template_label_always_to_be_reported -> B3 - Total Energy Consumption (in MWh) from - to - [Always to be reported]
C3: 29
C4: 18-25
C5: =template_label_total_energy_consumption -> Total Energy Consumption | L5: =IF(AND(OR('General Information'!E122="Option A (Basic Module only)", 'General Information'!E122="Option B (Basic Module and Comprehensive Module)"), G5=""), template_label_missing_value, IF('General Information'!E122="", "", template_label_ok))
C7: =template_label_b3_breakdown_of_energy_consumption&" "&template_label_from&" "&template_starting_date_display&" "&template_label_to&" "&template_ending_date_display&" "&template_label_if_applicable -> B3 - Breakdown of energy consumption (in MWh) from - to - [If applicable]
C8: 29
C9: 18-25
C10: =template_label_has_the_undertaking_obtained_the_necessary_information_to_provide_an_energy_consumption_breakdown -> Has the undertaking obtained the necessary information to provide an energy consumption breakdown? | G10: FALSE
G11: =template_label_renewable -> Renewable | J11: =template_label_non_renewable -> Non-renewable | K11: =template_label_total_renewable_and_nonrenewable -> Total renewable and non-renewable
C12: =template_label_electricity -> Electricity (as reflected in utility billings) | K12: =IF(AND(G12="",J12=""),"-",SUM(G12:J12)) -> - | L12: {=IF(G10=TRUE, IF(SUMPRODUCT(--(G12:J14<>"-"), --(G12:J14<>""))>0, IF(SUM(G12:J14) > TotalEnergyConsumption, template_label_value_inconsistency, template_label_ok), template_label_missing_value), "")}
C13: =template_label_selfgenerated_electricity -> Self-generated electricity | K13: =IF(AND(G13="",J13=""),"-",SUM(G13:J13)) -> -
C14: =template_label_fuels -> Fuels (see Fuel Converter on Fuels worksheet) | G14: =IF('Fuel Converter'!D23=TRUE, 'Fuel Converter'!A32, "-") -> - | J14: =IF('Fuel Converter'!D23=TRUE, 'Fuel Converter'!B32, "-") -> - | K14: =IF(AND(G14="-",J14="-"),"-",SUM(G14:J14)) -> - | M14: =template_label_energy_consumption_warning -> ℹ️ Please note that the formula present in this cell may be overwritten in case the undertaking wants to directly provide the value.
C16: =template_label_b3_estimated_greenhouse_gas_emissions& " "&template_label_always_to_be_reported -> B3 - Estimated Greenhouse Gas Emissions considering the GHG Protocol Version 2004 (in tCO2e) [Always to be reported] | G16: =template_label_c3_ghg_reduction_targets&" "&template_label_if_applicable -> C3 - GHG reduction targets (in tC02e) [If applicable]
C17: 30 | G17: 54(b) | J17: 54(a) | K17: 54(d)
C18: N/A | D18: 26-45 | G18: 152-158 | J18: 152-158 | K18: 152-158
G19: =template_label_has_the_undertaking_has_established_ghg_emission_reduction_targets -> Has the undertaking has established GHG emission reduction targets? | J19: FALSE
D20: =template_label_current_reporting_period -> Current Reporting Period | G20: =template_label_base_year -> Base Year | J20: =template_label_target_year -> Target Year | K20: =template_label_percentage_reduction_from_base_year -> Percentage reduction from base year
A21: =template_label_GHG_calculator -> ℹ️ Check EFRAG website for a non-exhaustive list of GHG calculators. | C21: =template_label_year_date -> Year (date) | D21: =IF('General Information'!$D$9="", "-", 'General Information'!$D$9) & " - " & IF('General Information'!$D$13="", "-", 'General Information'!$D$13) -> - - - | L21: =IF(AND(J19=TRUE, G21<>"", J21<>""), template_label_ok, IF(AND(J19=TRUE, G21="", J21=""), template_label_missing_value, IF(AND(J19=FALSE, G21="", J21=""), "", IF(AND(J19=TRUE, OR(G21="", J21="")), template_label_missing_value, ""))))
C22: =template_label_gross_scope_1_ghg_emissions -> Gross Scope 1 GHG Emissions | K22: =IF(AND(G22="", J22=""), "-", IFERROR(-(1 - (J22 / G22)), "-")) -> - | L22: =IF(AND(OR(BasisForPreparation="Option A (Basic Module Only)", BasisForPreparation="Option B (Basic Module and Comprehensive Module)"), D22="", J19=FALSE), template_label_missing_value, IF(AND(OR(BasisForPreparation="Option A (Basic Module Only)", BasisForPreparation="Option B (Basic Module and Comprehensive Module)"), D22<>"", G22<>"", J22<>"", J19=TRUE), template_label_ok, IF(AND(BasisForPreparation="Option A (Basic Module Only)", D22<>"", OR(G22="", J22=""), J19=FALSE), template_label_ok, IF(AND(BasisForPreparation="Option A (Basic Module Only)", D22<>"", OR(G22="", J22=""), J19=TRUE), template_label_missing_value, IF(AND(BasisForPreparation="Option B (Basic Module and Comprehensive Module)", D22<>"", OR(G22="", J22=""), J19=TRUE), template_label_missing_value, IF(AND(BasisForPreparation="Option B (Basic Module and Comprehensive Module)", D22="", OR(G22="", J22=""), J19=TRUE), template_label_missing_value, IF(AND(BasisForPreparation="Option A (Basic Module Only)", D22<>"", G22="", J22="", J19=FALSE), template_label_ok, IF(AND(BasisForPreparation="Option B (Basic Module and Comprehensive Module)", D22<>"", G22="", J22="", J19=FALSE), template_label_ok, IF(OR(BasisForPreparation="", D22="", G22="", J22="", J19=FALSE), "", template_label_missing_value)))))))))
C23: =template_label_gross_scope_2_location_based_ghg_emissions -> Gross Scope 2 location-based GHG Emissions | K23: =IF(AND(G23="", J23=""), "-", IFERROR(-(1 - (J23 / G23)), "-")) -> - | L23: =IF(AND(OR(BasisForPreparation="Option A (Basic Module Only)", BasisForPreparation="Option B (Basic Module and Comprehensive Module)"), D23="", J19=FALSE), template_label_missing_value, IF(AND(OR(BasisForPreparation="Option A (Basic Module Only)", BasisForPreparation="Option B (Basic Module and Comprehensive Module)"), D23<>"", G23<>"", J23<>"", J19=TRUE), template_label_ok, IF(AND(BasisForPreparation="Option A (Basic Module Only)", D23<>"", OR(G23="", J23=""), J19=FALSE), template_label_ok, IF(AND(BasisForPreparation="Option A (Basic Module Only)", D23<>"", OR(G23="", J23=""), J19=TRUE), template_label_missing_value, IF(AND(BasisForPreparation="Option B (Basic Module and Comprehensive Module)", D23<>"", OR(G23="", J23=""), J19=TRUE), template_label_missing_value, IF(AND(BasisForPreparation="Option B (Basic Module and Comprehensive Module)", D23="", OR(G23="", J23=""), J19=TRUE), template_label_missing_value, IF(AND(BasisForPreparation="Option A (Basic Module Only)", D23<>"", G23="", J23="", J19=FALSE), template_label_ok, IF(AND(BasisForPreparation="Option B (Basic Module and Comprehensive Module)", D23<>"", G23="", J23="", J19=FALSE), template_label_ok, IF(OR(BasisForPreparation="", D23="", G23="", J23="", J19=FALSE), "", template_label_missing_value)))))))))
C24: =template_label_gross_scope_2_market_based_ghg_emissions & " - " & template_label_may_not_headline -> Gross scope 2 market-based GHG Emissions - May (optional) | K24: =IF(AND(G24="", J24=""), "-", IFERROR(-(1 - (J24 / G24)), "-")) -> - | L24: =IF(D24<>"", IF(AND(G24="", J24=""), template_label_ok, IF(AND(G24<>"", J24=""), template_label_missing_value, template_label_ok) ), "")
C25: =template_label_total_scope_1_and_scope_2_ghg_emissions_location_based -> Total Scope 1 and Scope 2 GHG Emissions (location-based) | D25: =IF(AND(D22="",D23=""),"-",SUM(D22,D23)) -> - | G25: =IF(AND(G22="",G23=""),"-",SUM(G22,G23)) -> - | J25: =IF(AND(J22="",J23=""),"-",SUM(J22,J23)) -> - | K25: =IF(AND(G25="", J25=""), "-", IFERROR(-(1 - (J25 / G25)), "-")) -> -
C26: =template_label_total_scope_1_and_scope_2_ghg_emissions_market_based & " - " & template_label_may_not_headline -> Total Scope 1 and Scope 2 GHG emissions (market-based) - May (optional) | D26: =IF(OR(D22="",D24=""),"-",SUM(D22,D24)) -> - | G26: =IF(OR(G22="",G24=""),"-",SUM(G22,G24)) -> - | J26: =IF(OR(J22="",J24=""),"-",SUM(J22,J24)) -> - | K26: =IF(AND(G26="", J26=""), "-", IFERROR(-(1 - (J26 / G26)), "-")) -> -
C27: 50-53 | G27: 54
C28: N/A | D28: 150-151 | G28: N/A | J28: N/A
C29: =template_label_is_the_undertaking_disclosing_entity_specific_information_on_scope_3_emissions -> Is the undertaking disclosing entity-specific information on Scope 3 emissions (in tCO2e)? | G29: FALSE
C30: =template_label_1_purchased_goods_and_services -> 1. Purchased Goods and Services | K30: =IF(OR(G30="", J30=""), "-", IFERROR(-(1 - (J30 / G30)), "-")) -> - | L30: {=IF( OR( SUMPRODUCT((G30:G44<>"")*(J30:J44="")) > 0, SUMPRODUCT((J30:J44<>"")*(G30:G44="")) > 0 ), template_label_missing_value, IF( AND(G29=TRUE, COUNTA(D30:F44)=0), template_label_missing_value, IF(G29=FALSE, "", template_label_ok) ) )} | M30: =template_label_scope_3_categories_warning -> ℹ️ Scope 3 categories according to the GHG protocol might help to calculate the total Scope 3 GHG emissions. In case the undertaking wants to, it can directly provide the Total Scope 3 GHG emissions in the respective cell.
C31: =template_label_2_capital_goods -> 2. Capital Goods | K31: =IF(OR(G31="", J31=""), "-", IFERROR(-(1 - (J31 / G31)), "-")) -> -
C32: =template_label_3_fuel__and_energy_related_activities -> 3. Fuel- and Energy-Related Activities (Not Included in Scope 1 or Scope 2) | K32: =IF(OR(G32="", J32=""), "-", IFERROR(-(1 - (J32 / G32)), "-")) -> -
C33: =template_label_4_upstream_transportation_and_distribution -> 4. Upstream Transportation and Distribution | K33: =IF(OR(G33="", J33=""), "-", IFERROR(-(1 - (J33 / G33)), "-")) -> -
C34: =template_label_5_waste_generated_in_operations -> 5. Waste Generated in Operations | K34: =IF(OR(G34="", J34=""), "-", IFERROR(-(1 - (J34 / G34)), "-")) -> -
C35: =template_label_6_business_travel -> 6. Business Travel | K35: =IF(OR(G35="", J35=""), "-", IFERROR(-(1 - (J35 / G35)), "-")) -> -
C36: =template_label_7_employee_commuting -> 7. Employee Commuting | K36: =IF(OR(G36="", J36=""), "-", IFERROR(-(1 - (J36 / G36)), "-")) -> -
C37: =template_label_8_upstream_leased_assets -> 8. Upstream Leased Assets | K37: =IF(OR(G37="", J37=""), "-", IFERROR(-(1 - (J37 / G37)), "-")) -> -
C38: =template_label_9_downstream_transportation_and_distribution -> 9. Downstream Transportation and Distribution | K38: =IF(OR(G38="", J38=""), "-", IFERROR(-(1 - (J38 / G38)), "-")) -> -
C39: =template_label_10_processing_of_sold_products -> 10. Processing of Sold Products | K39: =IF(OR(G39="", J39=""), "-", IFERROR(-(1 - (J39 / G39)), "-")) -> -
C40: =template_label_11_use_of_sold_products -> 11. Use of Sold Products | K40: =IF(OR(G40="", J40=""), "-", IFERROR(-(1 - (J40 / G40)), "-")) -> -
